Workbook

Sheet DATA
CL1: Options :
CL2: Q1 2024
CL3: Q2 2024
F4: ACTIVE TABLE FOR SELECTED | CL4: Q3 2024
CL5: Q4 2024
C7: NAME | D7: {=_xlfn.SWITCH(DASHBOARD!M1,CL2,D25:AS32,CL3,D35:AS42,CL4,D45:AS52,CL5,D55:AS62)} -> July | E7: August | F7: September | G7: July | H7: August | I7: September | J7: July | K7: August | L7: September | M7: July | N7: August | O7: September | P7: July | Q7: August | R7: September | S7: July | T7: August | U7: September | V7: July | W7: August | X7: September | Y7: July | Z7: August | AA7: September | AB7: July | AC7: August | AD7: September | AE7: July | AF7: August | AG7: September | AH7: July | AI7: August | AJ7: September | AK7: July | AL7: August | AM7: September | AN7: July | AO7: August | AP7: September | AQ7: July | AR7: August | AS7: September
D8: Revenue | E8: Revenue | F8: Revenue | G8: Target Revenue | H8: Target Revenue | I8: Target Revenue | J8: Previous Year Revenue | K8: Previous Year Revenue | L8: Previous Year Revenue | M8: Number of Customers | N8: Number of Customers | O8: Number of Customers | P8: Number of New Customers Target | Q8: Number of New Customers Target | R8: Number of New Customers Target | S8: Number of New Customers | T8: Number of New Customers | U8: Number of New Customers | V8: Number of New Customers Previous Year | W8: Number of New Customers Previous Year | X8: Number of New Customers Previous Year | Y8: Customer Acquisition Costs | Z8: Customer Acquisition Costs | AA8: Customer Acquisition Costs | AB8: Customer AC (per customer) | AC8: Customer AC (per customer) | AD8: Customer AC (per customer) | AE8: Customer AC (per customer) Target | AF8: Customer AC (per customer) Target | AG8: Customer AC (per customer) Target | AH8: Customer Aquis. Costs (per customer) PY | AI8: Customer Aquis. Costs (per customer) PY | AJ8: Customer Aquis. Costs (per customer) PY | AK8: Revenue per Customer | AL8: Revenue per Customer | AM8: Revenue per Customer | AN8: Revenue per Customer PY | AO8: Revenue per Customer PY | AP8: Revenue per Customer PY | AQ8: Target Revenue per Customer | AR8: Target Revenue per Customer | AS8: Target Revenue per Customer
C9: Yusuf | D9: 150000 | E9: 145000 | F9: 145000 | G9: 160000 | H9: 145000 | I9: 160000 | J9: 160000 | K9: 125000 | L9: 145000 | M9: 55 | N9: 55 | O9: 60 | P9: 20 | Q9: 25 | R9: 35 | S9: 14 | T9: 18 | U9: 17 | V9: 21 | W9: 15 | X9: 11 | Y9: 8000 | Z9: 6000 | AA9: 4000 | AB9: 571.43 | AC9: 333.33 | AD9: 235.29 | AE9: 350 | AF9: 450 | AG9: 350 | AH9: 400 | AI9: 385 | AJ9: 390 | AK9: 2909.09 | AL9: 2636.36 | AM9: 2416.67 | AN9: 2800 | AO9: 2500 | AP9: 2300 | AQ9: 2200 | AR9: 2300 | AS9: 2500
C10: Arfat | D10: 185000 | E10: 150000 | F10: 185000 | G10: 160000 | H10: 145000 | I10: 160000 | J10: 125000 | K10: 130000 | L10: 120000 | M10: 56 | N10: 45 | O10: 65 | P10: 20 | Q10: 25 | R10: 35 | S10: 15 | T10: 25 | U10: 25 | V10: 14 | W10: 22 | X10: 12 | Y10: 5500 | Z10: 8500 | AA10: 5000 | AB10: 366.67 | AC10: 340 | AD10: 200 | AE10: 350 | AF10: 450 | AG10: 350 | AH10: 380 | AI10: 400 | AJ10: 388 | AK10: 3303.57 | AL10: 3333.33 | AM10: 2846.15 | AN10: 2500 | AO10: 3000 | AP10: 2000 | AQ10: 2200 | AR10: 2300 | AS10: 2500
C11: Aditi | D11: 150000 | E11: 125000 | F11: 120000 | G11: 160000 | H11: 145000 | I11: 160000 | J11: 130000 | K11: 150000 | L11: 125000 | M11: 56 | N11: 65 | O11: 50 | P11: 20 | Q11: 25 | R11: 35 | S11: 22 | T11: 17 | U11: 17 | V11: 25 | W11: 17 | X11: 21 | Y11: 9000 | Z11: 6500 | AA11: 6500 | AB11: 409.09 | AC11: 382.35 | AD11: 382.35 | AE11: 350 | AF11: 450 | AG11: 350 | AH11: 365 | AI11: 350 | AJ11: 352 | AK11: 2678.57 | AL11: 1923.08 | AM11: 2400 | AN11: 2600 | AO11: 1800 | AP11: 2200 | AQ11: 2200 | AR11: 2300 | AS11: 2500
C12: Pravin | D12: 155000 | E12: 155000 | F12: 155000 | G12: 160000 | H12: 145000 | I12: 160000 | J12: 150000 | K12: 155000 | L12: 160000 | M12: 62 | N12: 52 | O12: 52 | P12: 20 | Q12: 25 | R12: 35 | S12: 21 | T12: 24 | U12: 22 | V12: 17 | W12: 16 | X12: 23 | Y12: 6200 | Z12: 6300 | AA12: 9000 | AB12: 295.24 | AC12: 262.5 | AD12: 409.09 | AE12: 350 | AF12: 450 | AG12: 350 | AH12: 405 | AI12: 370 | AJ12: 350 | AK12: 2500 | AL12: 2980.77 | AM12: 2980.77 | AN12: 2400 | AO12: 2800 | AP12: 2890 | AQ12: 2200 | AR12: 2300 | AS12: 2500
C13: Owais | D13: 140000 | E13: 170000 | F13: 155000 | G13: 160000 | H13: 145000 | I13: 160000 | J13: 150000 | K13: 180000 | L13: 140000 | M13: 65 | N13: 50 | O13: 70 | P13: 20 | Q13: 25 | R13: 35 | S13: 30 | T13: 16 | U13: 18 | V13: 25 | W13: 21 | X13: 20 | Y13: 9800 | Z13: 8000 | AA13: 7500 | AB13: 326.67 | AC13: 500 | AD13: 416.67 | AE13: 350 | AF13: 450 | AG13: 350 | AH13: 385 | AI13: 350 | AJ13: 410 | AK13: 2153.85 | AL13: 3400 | AM13: 2214.29 | AN13: 1900 | AO13: 3000 | AP13: 2100 | AQ13: 2200 | AR13: 2300 | AS13: 2500
C14: TOTAL | D14: 780000 | E14: 745000 | F14: 760000 | G14: 800000 | H14: 725000 | I14: 800000 | J14: 715000 | K14: 740000 | L14: 690000 | M14: 294 | N14: 267 | O14: 297 | P14: 100 | Q14: 125 | R14: 175 | S14: 102 | T14: 100 | U14: 99 | V14: 102 | W14: 91 | X14: 87 | Y14: 38500 | Z14: 35300 | AA14: 32000 | AB14: 393.82 | AC14: 363.636 | AD14: 328.68 | AE14: 350 | AF14: 450 | AG14: 350 | AH14: 387 | AI14: 371 | AJ14: 378 | AK14: 2709.016 | AL14: 2854.708 | AM14: 2571.576 | AN14: 2440 | AO14: 2620 | AP14: 2298 | AQ14: 2200 | AR14: 2300 | AS14: 2500
C16: TOTAL REVENUE PER YEAR | D16: =SUM(D32:F32,D42:F42,D52:F52,D62:F62) -> 9271500
C17: TOTAL CUSTOMERS PER YEAR | D17: =SUM(M32:O32,M42:O42,M52:O52,M62:O62) -> 3799
C18: NEW CUSTOMERS PER YEAR | D18: =SUM(S32:U32,S42:U42,S52:U52,S62:U62) -> 1228
C19: REVENUE PER CUSTOMER | D19: =D16/D17 -> 2440.5107
E22: Actual Data
B25: Q1 2024 | C25: NAME | D25: January | E25: February | F25: March | G25: January | H25: February | I25: March | J25: January | K25: February | L25: March | M25: January | N25: February | O25: March | P25: January | Q25: February | R25: March | S25: January | T25: February | U25: March | V25: January | W25: February | X25: March | Y25: January | Z25: February | AA25: March | AB25: January | AC25: February | AD25: March | AE25: January | AF25: February | AG25: March | AH25: January | AI25: February | AJ25: March | AK25: January | AL25: February | AM25: March | AN25: January | AO25: February | AP25: March | AQ25: January | AR25: February | AS25: March
D26: Revenue | E26: Revenue | F26: Revenue | G26: Target Revenue | H26: Target Revenue | I26: Target Revenue | J26: Previous Year Revenue | K26: Previous Year Revenue | L26: Previous Year Revenue | M26: Number of Customers | N26: Number of Customers | O26: Number of Customers | P26: Number of New Customers Target | Q26: Number of New Customers Target | R26: Number of New Customers Target | S26: Number of New Customers | T26: Number of New Customers | U26: Number of New Customers | V26: Number of New Customers Previous Year | W26: Number of New Customers Previous Year | X26: Number of New Customers Previous Year | Y26: Customer Acquisition Costs | Z26: Customer Acquisition Costs | AA26: Customer Acquisition Costs | AB26: Customer AC (per customer) | AC26: Customer AC (per customer) | AD26: Customer AC (per customer) | AE26: Customer AC (per customer) Target | AF26: Customer AC (per customer) Target | AG26: Customer AC (per customer) Target | AH26: Customer Aquis. Costs (per customer) PY | AI26: Customer Aquis. Costs (per customer) PY | AJ26: Customer Aquis. Costs (per customer) PY | AK26: Revenue per Customer | AL26: Revenue per Customer | AM26: Revenue per Customer | AN26: Revenue per Customer PY | AO26: Revenue per Customer PY | AP26: Revenue per Customer PY | AQ26: Target Revenue per Customer | AR26: Target Revenue per Customer | AS26: Target Revenue per Customer
C27: Yusuf | D27: 135000 | E27: 130000 | F27: 160000 | G27: 150000 | H27: 140000 | I27: 150000 | J27: 115000 | K27: 140000 | L27: 160000 | M27: 57 | N27: 58 | O27: 63 | P27: 25 | Q27: 20 | R27: 25 | S27: 10 | T27: 11 | U27: 18 | V27: 9 | W27: 12 | X27: 14 | Y27: 4200 | Z27: 5000 | AA27: 5500 | AB27: 420 | AC27: 454.55 | AD27: 305.56 | AE27: 350 | AF27: 350 | AG27: 350 | AH27: 400 | AI27: 385 | AJ27: 390 | AK27: 2192.98 | AL27: 2241.38 | AM27: 2539.68 | AN27: 2200 | AO27: 2100 | AP27: 2400 | AQ27: 2500 | AR27: 2600 | AS27: 2400
C28: Arfat | D28: 170000 | E28: 160000 | F28: 185000 | G28: 150000 | H28: 140000 | I28: 150000 | J28: 160000 | K28: 130000 | L28: 125000 | M28: 74 | N28: 70 | O28: 74 | P28: 25 | Q28: 20 | R28: 25 | S28: 22 | T28: 23 | U28: 26 | V28: 17 | W28: 24 | X28: 22 | Y28: 7800 | Z28: 10000 | AA28: 9000 | AB28: 354.55 | AC28: 434.78 | AD28: 346.15 | AE28: 350 | AF28: 350 | AG28: 350 | AH28: 402 | AI28: 290 | AJ28: 380 | AK28: 2432.43 | AL28: 2285.71 | AM28: 2500 | AN28: 2100 | AO28: 2200 | AP28: 2300 | AQ28: 2500 | AR28: 2600 | AS28: 2400
C29: Aditi | D29: 175000 | E29: 135000 | F29: 145000 | G29: 150000 | H29: 140000 | I29: 150000 | J29: 170000 | K29: 145000 | L29: 130000 | M29: 70 | N29: 55 | O29: 61 | P29: 25 | Q29: 20 | R29: 25 | S29: 35 | T29: 20 | U29: 17 | V29: 36 | W29: 25 | X29: 21 | Y29: 13200 | Z29: 9500 | AA29: 8300 | AB29: 377.14 | AC29: 475 | AD29: 488.24 | AE29: 350 | AF29: 350 | AG29: 350 | AH29: 350 | AI29: 385 | AJ29: 352 | AK29: 2428.57 | AL29: 2454.55 | AM29: 2377.05 | AN29: 2500 | AO29: 2500 | AP29: 2300 | AQ29: 2500 | AR29: 2600 | AS29: 2400
C30: Pravin | D30: 156000 | E30: 175000 | F30: 155000 | G30: 150000 | H30: 140000 | I30: 150000 | J30: 165000 | K30: 155000 | L30: 140000 | M30: 66 | N30: 68 | O30: 63 | P30: 25 | Q30: 20 | R30: 25 | S30: 18 | T30: 14 | U30: 24 | V30: 14 | W30: 25 | X30: 22 | Y30: 6500 | Z30: 9000 | AA30: 8500 | AB30: 361.11 | AC30: 642.86 | AD30: 354.17 | AE30: 350 | AF30: 350 | AG30: 350 | AH30: 350 | AI30: 360 | AJ30: 388 | AK30: 2272.73 | AL30: 2573.53 | AM30: 2460.32 | AN30: 2200 | AO30: 2600 | AP30: 2400 | AQ30: 2500 | AR30: 2600 | AS30: 2400
C31: Owais | D31: 135500 | E31: 190000 | F31: 140000 | G31: 150000 | H31: 140000 | I31: 150000 | J31: 155000 | K31: 120000 | L31: 150000 | M31: 71 | N31: 62 | O31: 51 | P31: 25 | Q31: 20 | R31: 25 | S31: 33 | T31: 20 | U31: 16 | V31: 20 | W31: 25 | X31: 24 | Y31: 12100 | Z31: 10800 | AA31: 10500 | AB31: 366.67 | AC31: 540 | AD31: 656.25 | AE31: 350 | AF31: 350 | AG31: 350 | AH31: 385 | AI31: 350 | AJ31: 406 | AK31: 1901.41 | AL31: 3064.52 | AM31: 2745.1 | AN31: 2100 | AO31: 2800 | AP31: 2700 | AQ31: 2500 | AR31: 2600 | AS31: 2400
C32: TOTAL | D32: =SUM(D27:D31) -> 771500 | E32: =SUM(E27:E31) -> 790000 | F32: =SUM(F27:F31) -> 785000 | G32: =SUM(G27:G31) -> 750000 | H32: =SUM(H27:H31) -> 700000 | I32: =SUM(I27:I31) -> 750000 | J32: =SUM(J27:J31) -> 765000 | K32: =SUM(K27:K31) -> 690000 | ... AA32: =SUM(AA27:AA31) -> 41800 | AB32: =AVERAGE(AB27:AB31) -> 375.894 | AC32: =AVERAGE(AC27:AC31) -> 509.438 | AD32: =AVERAGE(AD27:AD31) -> 430.074 | AE32: =AVERAGE(AE27:AE31) -> 350 | AF32: =AVERAGE(AF27:AF31) -> 350 | AG32: =AVERAGE(AG27:AG31) -> 350 | AH32: =AVERAGE(AH27:AH31) -> 377.4 | AI32: =AVERAGE(AI27:AI31) -> 354 | ... AS32: =AVERAGE(AS27:AS31) -> 2400
B35: Q2 2024 | C35: NAME | D35: April | E35: May | F35: June | G35: April | H35: May | I35: June | J35: April | K35: May | L35: June | M35: April | N35: May | O35: June | P35: April | Q35: May | R35: June | S35: April | T35: May | U35: June | V35: April | W35: May | X35: June | Y35: April | Z35: May | AA35: June | AB35: April | AC35: May | AD35: June | AE35: April | AF35: May | AG35: June | AH35: April | AI35: May | AJ35: June | AK35: April | AL35: May | AM35: June | AN35: April | AO35: May | AP35: June | AQ35: April | AR35: May | AS35: June
D36: Revenue | E36: Revenue | F36: Revenue | G36: Target Revenue | H36: Target Revenue | I36: Target Revenue | J36: Previous Year Revenue | K36: Previous Year Revenue | L36: Previous Year Revenue | M36: Number of Customers | N36: Number of Customers | O36: Number of Customers | P36: Number of New Customers Target | Q36: Number of New Customers Target | R36: Number of New Customers Target | S36: Number of New Customers | T36: Number of New Customers | U36: Number of New Customers | V36: Number of New Customers Previous Year | W36: Number of New Customers Previous Year | X36: Number of New Customers Previous Year | Y36: Customer Acquisition Costs | Z36: Customer Acquisition Costs | AA36: Customer Acquisition Costs | AB36: Customer AC (per customer) | AC36: Customer AC (per customer) | AD36: Customer AC (per customer) | AE36: Customer AC (per customer) Target | AF36: Customer AC (per customer) Target | AG36: Customer AC (per customer) Target | AH36: Customer Aquis. Costs (per customer) PY | AI36: Customer Aquis. Costs (per customer) PY | AJ36: Customer Aquis. Costs (per customer) PY | AK36: Revenue per Customer | AL36: Revenue per Customer | AM36: Revenue per Customer | AN36: Revenue per Customer PY | AO36: Revenue per Customer PY | AP36: Revenue per Customer PY | AQ36: Target Revenue per Customer | AR36: Target Revenue per Customer | AS36: Target Revenue per Customer
C37: Yusuf | D37: 130000 | E37: 135000 | F37: 150000 | G37: 150000 | H37: 160000 | I37: 140000 | J37: 125000 | K37: 160000 | L37: 135000 | M37: 58 | N37: 63 | O37: 55 | P37: 30 | Q37: 30 | R37: 25 | S37: 12 | T37: 25 | U37: 11 | V37: 11 | W37: 21 | X37: 14 | Y37: 5000 | Z37: 4500 | AA37: 5000 | AB37: 416.67 | AC37: 180 | AD37: 454.55 | AE37: 400 | AF37: 350 | AG37: 350 | AH37: 400 | AI37: 385 | AJ37: 390 | AK37: 2068.97 | AL37: 2142.86 | AM37: 2727.27 | AN37: 2100 | AO37: 2000 | AP37: 2600 | AQ37: 2700 | AR37: 2500 | AS37: 2600
C38: Arfat | D38: 175000 | E38: 155000 | F38: 190000 | G38: 150000 | H38: 160000 | I38: 140000 | J38: 145000 | K38: 125000 | L38: 125000 | M38: 70 | N38: 74 | O38: 65 | P38: 30 | Q38: 30 | R38: 25 | S38: 26 | T38: 18 | U38: 23 | V38: 17 | W38: 18 | X38: 15 | Y38: 9800 | Z38: 9800 | AA38: 6500 | AB38: 376.92 | AC38: 544.44 | AD38: 282.61 | AE38: 400 | AF38: 350 | AG38: 350 | AH38: 402 | AI38: 290 | AJ38: 380 | AK38: 2500 | AL38: 2094.59 | AM38: 2923.08 | AN38: 2200 | AO38: 2000 | AP38: 2200 | AQ38: 2700 | AR38: 2500 | AS38: 2600
C39: Aditi | D39: 180000 | E39: 145000 | F39: 155000 | G39: 150000 | H39: 160000 | I39: 140000 | J39: 155000 | K39: 130000 | L39: 125000 | M39: 55 | N39: 61 | O39: 44 | P39: 30 | Q39: 30 | R39: 25 | S39: 31 | T39: 25 | U39: 20 | V39: 25 | W39: 21 | X39: 22 | Y39: 9500 | Z39: 10200 | AA39: 8000 | AB39: 306.45 | AC39: 408 | AD39: 400 | AE39: 400 | AF39: 350 | AG39: 350 | AH39: 350 | AI39: 385 | AJ39: 352 | AK39: 3272.73 | AL39: 2377.05 | AM39: 3522.73 | AN39: 3000 | AO39: 2200 | AP39: 2100 | AQ39: 2700 | AR39: 2500 | AS39: 2600
C40: Pravin | D40: 160000 | E40: 180000 | F40: 175000 | G40: 150000 | H40: 160000 | I40: 140000 | J40: 145000 | K40: 140000 | L40: 160000 | M40: 68 | N40: 63 | O40: 50 | P40: 30 | Q40: 30 | R40: 25 | S40: 28 | T40: 15 | U40: 14 | V40: 17 | W40: 18 | X40: 21 | Y40: 9000 | Z40: 5600 | AA40: 7000 | AB40: 321.43 | AC40: 373.33 | AD40: 500 | AE40: 400 | AF40: 350 | AG40: 350 | AH40: 350 | AI40: 360 | AJ40: 388 | AK40: 2352.94 | AL40: 2857.14 | AM40: 3500 | AN40: 2200 | AO40: 2450 | AP40: 3300 | AQ40: 2700 | AR40: 2500 | AS40: 2600
C41: Owais | D41: 205000 | E41: 195000 | F41: 125000 | G41: 150000 | H41: 160000 | I41: 140000 | J41: 125000 | K41: 150000 | L41: 145000 | M41: 62 | N41: 51 | O41: 35 | P41: 30 | Q41: 30 | R41: 25 | S41: 25 | T41: 18 | U41: 20 | V41: 20 | W41: 13 | X41: 20 | Y41: 10800 | Z41: 9500 | AA41: 9000 | AB41: 432 | AC41: 527.78 | AD41: 450 | AE41: 400 | AF41: 350 | AG41: 350 | AH41: 385 | AI41: 350 | AJ41: 406 | AK41: 3306.45 | AL41: 3823.53 | AM41: 3571.43 | AN41: 2900 | AO41: 3100 | AP41: 3100 | AQ41: 2700 | AR41: 2500 | AS41: 2600
C42: TOTAL | D42: =SUM(D37:D41) -> 850000 | E42: =SUM(E37:E41) -> 810000 | F42: =SUM(F37:F41) -> 795000 | G42: =SUM(G37:G41) -> 750000 | H42: =SUM(H37:H41) -> 800000 | I42: =SUM(I37:I41) -> 700000 | J42: =SUM(J37:J41) -> 695000 | K42: =SUM(K37:K41) -> 705000 | ... AA42: =SUM(AA37:AA41) -> 35500 | AB42: =AVERAGE(AB37:AB41) -> 370.694 | AC42: =AVERAGE(AC37:AC41) -> 406.71 | AD42: =AVERAGE(AD37:AD41) -> 417.432 | AE42: =AVERAGE(AE37:AE41) -> 400 | AF42: =AVERAGE(AF37:AF41) -> 350 | AG42: =AVERAGE(AG37:AG41) -> 350 | AH42: =AVERAGE(AH37:AH41) -> 377.4 | AI42: =AVERAGE(AI37:AI41) -> 354 | ... AS42: =AVERAGE(AS37:AS41) -> 2600
B45: Q3 2024 | C45: NAME | D45: July | E45: August | F45: September | G45: July | H45: August | I45: September | J45: July | K45: August | L45: September | M45: July | N45: August | O45: September | P45: July | Q45: August | R45: September | S45: July | T45: August | U45: September | V45: July | W45: August | X45: September | Y45: July | Z45: August | AA45: September | AB45: July | AC45: August | AD45: September | AE45: July | AF45: August | AG45: September | AH45: July | AI45: August | AJ45: September | AK45: July | AL45: August | AM45: September | AN45: July | AO45: August | AP45: September | AQ45: July | AR45: August | AS45: September
D46: Revenue | E46: Revenue | F46: Revenue | G46: Target Revenue | H46: Target Revenue | I46: Target Revenue | J46: Previous Year Revenue | K46: Previous Year Revenue | L46: Previous Year Revenue | M46: Number of Customers | N46: Number of Customers | O46: Number of Customers | P46: Number of New Customers Target | Q46: Number of New Customers Target | R46: Number of New Customers Target | S46: Number of New Customers | T46: Number of New Customers | U46: Number of New Customers | V46: Number of New Customers Previous Year | W46: Number of New Customers Previous Year | X46: Number of New Customers Previous Year | Y46: Customer Acquisition Costs | Z46: Customer Acquisition Costs | AA46: Customer Acquisition Costs | AB46: Customer AC (per customer) | AC46: Customer AC (per customer) | AD46: Customer AC (per customer) | AE46: Customer AC (per customer) Target | AF46: Customer AC (per customer) Target | AG46: Customer AC (per customer) Target | AH46: Customer Aquis. Costs (per customer) PY | AI46: Customer Aquis. Costs (per customer) PY | AJ46: Customer Aquis. Costs (per customer) PY | AK46: Revenue per Customer | AL46: Revenue per Customer | AM46: Revenue per Customer | AN46: Revenue per Customer PY | AO46: Revenue per Customer PY | AP46: Revenue per Customer PY | AQ46: Target Revenue per Customer | AR46: Target Revenue per Customer | AS46: Target Revenue per Customer
C47: Yusuf | D47: 150000 | E47: 145000 | F47: 145000 | G47: 160000 | H47: 145000 | I47: 160000 | J47: 160000 | K47: 125000 | L47: 145000 | M47: 55 | N47: 55 | O47: 60 | P47: 20 | Q47: 25 | R47: 35 | S47: 14 | T47: 18 | U47: 17 | V47: 21 | W47: 15 | X47: 11 | Y47: 8000 | Z47: 6000 | AA47: 4000 | AB47: 571.43 | AC47: 333.33 | AD47: 235.29 | AE47: 350 | AF47: 450 | AG47: 350 | AH47: 400 | AI47: 385 | AJ47: 390 | AK47: 2909.09 | AL47: 2636.36 | AM47: 2416.67 | AN47: 2800 | AO47: 2500 | AP47: 2300 | AQ47: 2200 | AR47: 2300 | AS47: 2500
C48: Arfat | D48: 185000 | E48: 150000 | F48: 185000 | G48: 160000 | H48: 145000 | I48: 160000 | J48: 125000 | K48: 130000 | L48: 120000 | M48: 56 | N48: 45 | O48: 65 | P48: 20 | Q48: 25 | R48: 35 | S48: 15 | T48: 25 | U48: 25 | V48: 14 | W48: 22 | X48: 12 | Y48: 5500 | Z48: 8500 | AA48: 5000 | AB48: 366.67 | AC48: 340 | AD48: 200 | AE48: 350 | AF48: 450 | AG48: 350 | AH48: 380 | AI48: 400 | AJ48: 388 | AK48: 3303.57 | AL48: 3333.33 | AM48: 2846.15 | AN48: 2500 | AO48: 3000 | AP48: 2000 | AQ48: 2200 | AR48: 2300 | AS48: 2500
C49: Aditi | D49: 150000 | E49: 125000 | F49: 120000 | G49: 160000 | H49: 145000 | I49: 160000 | J49: 130000 | K49: 150000 | L49: 125000 | M49: 56 | N49: 65 | O49: 50 | P49: 20 | Q49: 25 | R49: 35 | S49: 22 | T49: 17 | U49: 17 | V49: 25 | W49: 17 | X49: 21 | Y49: 9000 | Z49: 6500 | AA49: 6500 | AB49: 409.09 | AC49: 382.35 | AD49: 382.35 | AE49: 350 | AF49: 450 | AG49: 350 | AH49: 365 | AI49: 350 | AJ49: 352 | AK49: 2678.57 | AL49: 1923.08 | AM49: 2400 | AN49: 2600 | AO49: 1800 | AP49: 2200 | AQ49: 2200 | AR49: 2300 | AS49: 2500
C50: Pravin | D50: 155000 | E50: 155000 | F50: 155000 | G50: 160000 | H50: 145000 | I50: 160000 | J50: 150000 | K50: 155000 | L50: 160000 | M50: 62 | N50: 52 | O50: 52 | P50: 20 | Q50: 25 | R50: 35 | S50: 21 | T50: 24 | U50: 22 | V50: 17 | W50: 16 | X50: 23 | Y50: 6200 | Z50: 6300 | AA50: 9000 | AB50: 295.24 | AC50: 262.5 | AD50: 409.09 | AE50: 350 | AF50: 450 | AG50: 350 | AH50: 405 | AI50: 370 | AJ50: 350 | AK50: 2500 | AL50: 2980.77 | AM50: 2980.77 | AN50: 2400 | AO50: 2800 | AP50: 2890 | AQ50: 2200 | AR50: 2300 | AS50: 2500
...

Sheet DASHBOARD
M1: Q3 2024
B3: Revenue Compared Per Year | O3: New Customers Per Year
C7: =SUM(DATA!G14:I14) -> 2325000 | D7: Actual Revenue | P7: =SUM(DATA!S14:U14) -> 301 | R7: New Customers
C9: =SUM(DATA!J14:L14) -> 2145000 | D9: Previous Year Revenue | P9: =SUM(DATA!P14:R14) -> 400 | R9: Target Customers
P11: =P9/P7 -> 1.3289037 | R11: Target
C12: =C7/C9 -> 1.0839161 | D12: Target Achievement
B24: Average Revenue Per Year | O24: Customers Acquisitions Costs Per Year
C28: =SUM(DATA!AK14:AM14) -> 8135.3 | D28: Actual
Q29: =SUM(DATA!AB14:AD14) -> 1086.136 | R29: Actual
C30: =SUM(DATA!AN14:AP14) -> 7358 | D30: Target Revenue Per
Q31: =SUM(DATA!AH14:AJ14) -> 1136 | R31: Target
C32: =C28/C30 -> 1.1056401 | D32: Target
Q33: =Q29/Q31 -> 0.95610563 | R33: Target
